[2019-11-27 17:12:19,202: ERROR/MainProcess] consumer: Cannot connect to redis://localhost:6379/2: Error 111 connecting to localhost:6379. Connection refused..
Trying again in 2.00 seconds...

[2019-11-27 17:12:21,211: ERROR/MainProcess] consumer: Cannot connect to redis://localhost:6379/2: Error 111 connecting to localhost:6379. Connection refused..
Trying again in 4.00 seconds...

[2019-11-27 17:12:25,218: ERROR/MainProcess] consumer: Cannot connect to redis://localhost:6379/2: Error 111 connecting to localhost:6379. Connection refused..
Trying again in 6.00 seconds...

[2019-11-27 17:12:31,226: ERROR/MainProcess] consumer: Cannot connect to redis://localhost:6379/2: Error 111 connecting to localhost:6379. Connection refused..
Trying again in 8.00 seconds...

[2019-11-27 17:12:39,239: ERROR/MainProcess] consumer: Cannot connect to redis://localhost:6379/2: Error 111 connecting to localhost:6379. Connection refused..
Trying again in 10.00 seconds...

[2019-11-27 17:12:49,255: ERROR/MainProcess] consumer: Cannot connect to redis://localhost:6379/2: Error 111 connecting to localhost:6379. Connection refused..
Trying again in 12.00 seconds...

[2019-11-27 17:13:01,278: ERROR/MainProcess] consumer: Cannot connect to redis://localhost:6379/2: Error 111 connecting to localhost:6379. Connection refused..
Trying again in 14.00 seconds...

[2019-11-27 17:13:15,297: ERROR/MainProcess] consumer: Cannot connect to redis://localhost:6379/2: Error 111 connecting to localhost:6379. Connection refused..
Trying again in 16.00 seconds...

[2019-11-27 17:13:31,318: ERROR/MainProcess] consumer: Cannot connect to redis://localhost:6379/2: Error 111 connecting to localhost:6379. Connection refused..
Trying again in 18.00 seconds...

[2019-11-27 17:13:49,343: ERROR/MainProcess] consumer: Cannot connect to redis://localhost:6379/2: Error 111 connecting to localhost:6379. Connection refused..
Trying again in 20.00 seconds...

[2019-11-27 17:14:09,369: ERROR/MainProcess] consumer: Cannot connect to redis://localhost:6379/2: Error 111 connecting to localhost:6379. Connection refused..
Trying again in 22.00 seconds...

[2019-11-27 17:14:31,399: ERROR/MainProcess] consumer: Cannot connect to redis://localhost:6379/2: Error 111 connecting to localhost:6379. Connection refused..
Trying again in 24.00 seconds...

[2019-11-27 17:14:55,429: ERROR/MainProcess] consumer: Cannot connect to redis://localhost:6379/2: Error 111 connecting to localhost:6379. Connection refused..
Trying again in 26.00 seconds...

[2019-11-27 17:15:21,465: INFO/MainProcess] Connected to redis://localhost:6379/2
[2019-11-27 17:15:21,476: INFO/MainProcess] mingle: searching for neighbors
[2019-11-27 17:15:22,509: INFO/MainProcess] mingle: all alone
[2019-11-27 17:15:22,520: WARNING/MainProcess] /home/zheng/anaconda2/envs/tf/lib/python3.6/site-packages/celery/fixups/django.py:202: UserWarning: Using settings.DEBUG leads to a memory leak, never use this setting in production environments!
  warnings.warn('Using settings.DEBUG leads to a memory leak, never '
[2019-11-27 17:15:22,520: INFO/MainProcess] w1@zheng-pc ready.
[2019-11-27 17:15:25,297: INFO/MainProcess] Events of group {task} enabled by remote.
[2019-11-27 17:15:59,817: INFO/MainProcess] Received task: transform.tasks.transform_local[2df9e8ec-cb94-4f8b-9509-67837eb22903]  
[2019-11-27 17:16:35,961: INFO/MainProcess] Received task: transform.tasks.transform_local[e81a97e7-c8db-4034-9b6a-81c509fe3ace]  
[2019-11-27 17:25:13,442: INFO/MainProcess] Received task: transform.tasks.transform_local[35e196cc-f8a0-4405-9615-4667152aeecb]  
[2019-11-27 17:39:19,252: INFO/MainProcess] Received task: transform.tasks.transform_local[bae02b5c-910d-4044-a57d-ff8133f3b355]  
[2019-11-27 17:39:59,636: INFO/MainProcess] Received task: transform.tasks.transform_local[ed9b1f8d-a9c7-47aa-afc2-27d9eee2764f]  
[2019-11-27 17:41:40,951: INFO/MainProcess] Received task: transform.tasks.transform_local[0e824adc-2253-4ddb-8b5b-91cf57c908e9]  
[2019-11-27 17:41:41,590: ERROR/MainProcess] Pool callback raised exception: ResponseError('Command # 1 (SETEX b\'celery-task-meta-0e824adc-2253-4ddb-8b5b-91cf57c908e9\' 86400 b\'\\x80\\x02}q\\x00(X\\x06\\x00\\x00\\x00statusq\\x01X\\x07\\x00\\x00\\x00FAILUREq\\x02X\\x06\\x00\\x00\\x00resultq\\x03credis.exceptions\\nResponseError\\nq\\x04X\\xbd\\x17\\x00\\x00Command # 1 (SETEX b\\\'celery-task-meta-0e824adc-2253-4ddb-8b5b-91cf57c908e9\\\' 86400 b\\\'\\\\x80\\\\x02}q\\\\x00(X\\\\x06\\\\x00\\\\x00\\\\x00statusq\\\\x01X\\\\x07\\\\x00\\\\x00\\\\x00FAILUREq\\\\x02X\\\\x06\\\\x00\\\\x00\\\\x00resultq\\\\x03credis.exceptions\\\\nResponseError\\\\nq\\\\x04X\\\\x92\\\\x03\\\\x00\\\\x00Command # 1 (SETEX b\\\\\\\'celery-task-meta-0e824adc-2253-4ddb-8b5b-91cf57c908e9\\\\\\\' 86400 b\\\\\\\'\\\\\\\\x80\\\\\\\\x02}q\\\\\\\\x00(X\\\\\\\\x06\\\\\\\\x00\\\\\\\\x00\\\\\\\\x00statusq\\\\\\\\x01X\\\\\\\\x07\\\\\\\\x00\\\\\\\\x00\\\\\\\\x00SUCCESSq\\\\\\\\x02X\\\\\\\\x06\\\\\\\\x00\\\\\\\\x00\\\\\\\\x00resultq\\\\\\\\x03X\\\\\\\\x00\\\\\\\\x00\\\\\\\\x00\\\\\\\\x00q\\\\\\\\x04X\\\\\\\\t\\\\\\\\x00\\\\\\\\x00\\\\\\\\x00tracebackq\\\\\\\\x05NX\\\\\\\\x08\\\\\\\\x00\\\\\\\\x00\\\\\\\\x00childrenq\\\\\\\\x06]q\\\\\\\\x07X\\\\\\\\x07\\\\\\\\x00\\\\\\\\x00\\\\\\\\x00task_idq\\\\\\\\x08X$\\\\\\\\x00\\\\\\\\x00\\\\\\\\x000e824adc-2253-4ddb-8b5b-91cf57c908e9q\\\\\\\\tX\\\\\\\\t\\\\\\\\x00\\\\\\\\x00\\\\\\\\x00date_doneq\\\\\\\\ncdatetime\\\\\\\\ndatetime\\\\\\\\nq\\\\\\\\x0bc_codecs\\\\\\\\nencode\\\\\\\\nq\\\\\\\\x0cX\\\\\\\\x0b\\\\\\\\x00\\\\\\\\x00\\\\\\\\x00\\\\\\\\x07\\\\\\\\xc3\\\\\\\\xa3\\\\\\\\x0b\\\\\\\\x1b\\\\\\\\x11))\\\\\\\\x08z|q\\\\\\\\rX\\\\\\\\x06\\\\\\\\x00\\\\\\\\x00\\\\\\\\x00latin1q\\\\\\\\x0e\\\\\\\\x86q\\\\\\\\x0fRq\\\\\\\\x10\\\\\\\\x85q\\\\\\\\x11Rq\\\\\\\\x12u.\\\\\\\') of pipeline caused error: MISCONF Redis is configured to save RDB snapshots, but it is currently not able to persist on disk. Commands that may modify the data set are disabled, because this instance is configured to report errors during writes if RDB snapshotting fails (stop-writes-on-bgsave-error option). Please check the Redis logs for details about the RDB error.q\\\\x05\\\\x85q\\\\x06Rq\\\\x07X\\\\t\\\\x00\\\\x00\\\\x00tracebackq\\\\x08Xv\\\\x0f\\\\x00\\\\x00Traceback (most recent call last):\\\\n  File "/home/zheng/anaconda2/envs/tf/lib/python3.6/site-packages/redis/client.py", line 3584, in _execute_transaction\\\\n    response = self.parse_response(connection, \\\\\\\'_\\\\\\\')\\\\n  File "/home/zheng/anaconda2/envs/tf/lib/python3.6/site-packages/redis/client.py", line 3650, in parse_response\\\\n    self, connection, command_name, **options)\\\\n  File "/home/zheng/anaconda2/envs/tf/lib/python3.6/site-packages/redis/client.py", line 853, in parse_response\\\\n    response = connection.read_response()\\\\n  File "/home/zheng/anaconda2/envs/tf/lib/python3.6/site-packages/redis/connection.py", line 718, in read_response\\\\n    raise response\\\\nredis.exceptions.ExecAbortError: Transaction discarded because of previous errors.\\\\n\\\\nDuring handling of the above exception, another exception occurred:\\\\n\\\\nTraceback (most recent call last):\\\\n  File "/home/zheng/anaconda2/envs/tf/lib/python3.6/site-packages/celery/app/trace.py", line 449, in trace_task\\\\n    uuid, retval, task_request, publish_result,\\\\n  File "/home/zheng/anaconda2/envs/tf/lib/python3.6/site-packages/celery/backends/base.py", line 149, in mark_as_done\\\\n    self.store_result(task_id, result, state, request=request)\\\\n  File "/home/zheng/anaconda2/envs/tf/lib/python3.6/site-packages/celery/backends/base.py", line 342, in store_result\\\\n    request=request, **kwargs)\\\\n  File "/home/zheng/anaconda2/envs/tf/lib/python3.6/site-packages/celery/backends/base.py", line 714, in _store_result\\\\n    self.set(self.get_key_for_task(task_id), self.encode(meta))\\\\n  File "/home/zheng/anaconda2/envs/tf/lib/python3.6/site-packages/celery/backends/redis.py", line 318, in set\\\\n    return self.ensure(self._set, (key, value), **retry_policy)\\\\n  File "/home/zheng/anaconda2/envs/tf/lib/python3.6/site-packages/celery/backends/redis.py", line 308, in ensure\\\\n    **retry_policy)\\\\n  File "/home/zheng/anaconda2/envs/tf/lib/python3.6/site-packages/kombu/utils/functional.py", line 343, in retry_over_time\\\\n    return fun(*args, **kwargs)\\\\n  File "/home/zheng/anaconda2/envs/tf/lib/python3.6/site-packages/celery/backends/redis.py", line 327, in _set\\\\n    pipe.execute()\\\\n  File "/home/zheng/anaconda2/envs/tf/lib/python3.6/site-packages/redis/client.py", line 3691, in execute\\\\n    return execute(conn, stack, raise_on_error)\\\\n  File "/home/zheng/anaconda2/envs/tf/lib/python3.6/site-packages/redis/client.py", line 3589, in _execute_transaction\\\\n    raise errors[0][1]\\\\n  File "/home/zheng/anaconda2/envs/tf/lib/python3.6/site-packages/redis/client.py", line 3576, in _execute_transaction\\\\n    self.parse_response(connection, \\\\\\\'_\\\\\\\')\\\\n  File "/home/zheng/anaconda2/envs/tf/lib/python3.6/site-packages/redis/client.py", line 3650, in parse_response\\\\n    self, connection, command_name, **options)\\\\n  File "/home/zheng/anaconda2/envs/tf/lib/python3.6/site-packages/redis/client.py", line 853, in parse_response\\\\n    response = connection.read_response()\\\\n  File "/home/zheng/anaconda2/envs/tf/lib/python3.6/site-packages/redis/connection.py", line 718, in read_response\\\\n    raise response\\\\nredis.exceptions.ResponseError: Command # 1 (SETEX b\\\\\\\'celery-task-meta-0e824adc-2253-4ddb-8b5b-91cf57c908e9\\\\\\\' 86400 b\\\\\\\'\\\\\\\\x80\\\\\\\\x02}q\\\\\\\\x00(X\\\\\\\\x06\\\\\\\\x00\\\\\\\\x00\\\\\\\\x00statusq\\\\\\\\x01X\\\\\\\\x07\\\\\\\\x00\\\\\\\\x00\\\\\\\\x00SUCCESSq\\\\\\\\x02X\\\\\\\\x06\\\\\\\\x00\\\\\\\\x00\\\\\\\\x00resultq\\\\\\\\x03X\\\\\\\\x00\\\\\\\\x00\\\\\\\\x00\\\\\\\\x00q\\\\\\\\x04X\\\\\\\\t\\\\\\\\x00\\\\\\\\x00\\\\\\\\x00tracebackq\\\\\\\\x05NX\\\\\\\\x08\\\\\\\\x00\\\\\\\\x00\\\\\\\\x00childrenq\\\\\\\\x06]q\\\\\\\\x07X\\\\\\\\x07\\\\\\\\x00\\\\\\\\x00\\\\\\\\x00task_idq\\\\\\\\x08X$\\\\\\\\x00\\\\\\\\x00\\\\\\\\x000e824adc-2253-4ddb-8b5b-91cf57c908e9q\\\\\\\\tX\\\\\\\\t\\\\\\\\x00\\\\\\\\x00\\\\\\\\x00date_doneq\\\\\\\\ncdatetime\\\\\\\\ndatetime\\\\\\\\nq\\\\\\\\x0bc_codecs\\\\\\\\nencode\\\\\\\\nq\\\\\\\\x0cX\\\\\\\\x0b\\\\\\\\x00\\\\\\\\x00\\\\\\\\x00\\\\\\\\x07\\\\\\\\xc3\\\\\\\\xa3\\\\\\\\x0b\\\\\\\\x1b\\\\\\\\x11))\\\\\\\\x08z|q\\\\\\\\rX\\\\\\\\x06\\\\\\\\x00\\\\\\\\x00\\\\\\\\x00latin1q\\\\\\\\x0e\\\\\\\\x86q\\\\\\\\x0fRq\\\\\\\\x10\\\\\\\\x85q\\\\\\\\x11Rq\\\\\\\\x12u.\\\\\\\') of pipeline caused error: MISCONF Redis is configured to save RDB snapshots, but it is currently not able to persist on disk. Commands that may modify the data set are disabled, because this instance is configured to report errors during writes if RDB snapshotting fails (stop-writes-on-bgsave-error option). Please check the Redis logs for details about the RDB error.\\\\nq\\\\tX\\\\x08\\\\x00\\\\x00\\\\x00childrenq\\\\n]q\\\\x0bX\\\\x07\\\\x00\\\\x00\\\\x00task_idq\\\\x0cX$\\\\x00\\\\x00\\\\x000e824adc-2253-4ddb-8b5b-91cf57c908e9q\\\\rX\\\\t\\\\x00\\\\x00\\\\x00date_doneq\\\\x0ecdatetime\\\\ndatetime\\\\nq\\\\x0fc_codecs\\\\nencode\\\\nq\\\\x10X\\\\x0c\\\\x00\\\\x00\\\\x00\\\\x07\\\\xc3\\\\xa3\\\\x0b\\\\x1b\\\\x11))\\\\x08\\\\xc3\\\\x97\\\\x07q\\\\x11X\\\\x06\\\\x00\\\\x00\\\\x00latin1q\\\\x12\\\\x86q\\\\x13Rq\\\\x14\\\\x85q\\\\x15Rq\\\\x16u.\\\') of pipeline caused error: MISCONF Redis is configured to save RDB snapshots, but it is currently not able to persist on disk. Commands that may modify the data set are disabled, because this instance is configured to report errors during writes if RDB snapshotting fails (stop-writes-on-bgsave-error option). Please check the Redis logs for details about the RDB error.q\\x05\\x85q\\x06Rq\\x07X\\t\\x00\\x00\\x00tracebackq\\x08NX\\x08\\x00\\x00\\x00childrenq\\t]q\\nX\\x07\\x00\\x00\\x00task_idq\\x0bX$\\x00\\x00\\x000e824adc-2253-4ddb-8b5b-91cf57c908e9q\\x0cX\\t\\x00\\x00\\x00date_doneq\\rcdatetime\\ndatetime\\nq\\x0ec_codecs\\nencode\\nq\\x0fX\\r\\x00\\x00\\x00\\x07\\xc3\\xa3\\x0b\\x1b\\x11))\\x08\\xc3\\xbc\\xc3\\x86q\\x10X\\x06\\x00\\x00\\x00latin1q\\x11\\x86q\\x12Rq\\x13\\x85q\\x14Rq\\x15u.\') of pipeline caused error: MISCONF Redis is configured to save RDB snapshots, but it is currently not able to persist on disk. Commands that may modify the data set are disabled, because this instance is configured to report errors during writes if RDB snapshotting fails (stop-writes-on-bgsave-error option). Please check the Redis logs for details about the RDB error.',)
Traceback (most recent call last):
  File "/home/zheng/anaconda2/envs/tf/lib/python3.6/site-packages/redis/client.py", line 3584, in _execute_transaction
    response = self.parse_response(connection, '_')
  File "/home/zheng/anaconda2/envs/tf/lib/python3.6/site-packages/redis/client.py", line 3650, in parse_response
    self, connection, command_name, **options)
  File "/home/zheng/anaconda2/envs/tf/lib/python3.6/site-packages/redis/client.py", line 853, in parse_response
    response = connection.read_response()
  File "/home/zheng/anaconda2/envs/tf/lib/python3.6/site-packages/redis/connection.py", line 718, in read_response
    raise response
redis.exceptions.ExecAbortError: Transaction discarded because of previous errors.

During handling of the above exception, another exception occurred:

Traceback (most recent call last):
  File "/home/zheng/anaconda2/envs/tf/lib/python3.6/site-packages/billiard/pool.py", line 1791, in safe_apply_callback
    fun(*args, **kwargs)
  File "/home/zheng/anaconda2/envs/tf/lib/python3.6/site-packages/celery/worker/request.py", line 371, in on_failure
    store_result=self.store_errors,
  File "/home/zheng/anaconda2/envs/tf/lib/python3.6/site-packages/celery/backends/base.py", line 160, in mark_as_failure
    traceback=traceback, request=request)
  File "/home/zheng/anaconda2/envs/tf/lib/python3.6/site-packages/celery/backends/base.py", line 342, in store_result
    request=request, **kwargs)
  File "/home/zheng/anaconda2/envs/tf/lib/python3.6/site-packages/celery/backends/base.py", line 714, in _store_result
    self.set(self.get_key_for_task(task_id), self.encode(meta))
  File "/home/zheng/anaconda2/envs/tf/lib/python3.6/site-packages/celery/backends/redis.py", line 318, in set
    return self.ensure(self._set, (key, value), **retry_policy)
  File "/home/zheng/anaconda2/envs/tf/lib/python3.6/site-packages/celery/backends/redis.py", line 308, in ensure
    **retry_policy)
  File "/home/zheng/anaconda2/envs/tf/lib/python3.6/site-packages/kombu/utils/functional.py", line 343, in retry_over_time
    return fun(*args, **kwargs)
  File "/home/zheng/anaconda2/envs/tf/lib/python3.6/site-packages/celery/backends/redis.py", line 327, in _set
    pipe.execute()
  File "/home/zheng/anaconda2/envs/tf/lib/python3.6/site-packages/redis/client.py", line 3691, in execute
    return execute(conn, stack, raise_on_error)
  File "/home/zheng/anaconda2/envs/tf/lib/python3.6/site-packages/redis/client.py", line 3589, in _execute_transaction
    raise errors[0][1]
  File "/home/zheng/anaconda2/envs/tf/lib/python3.6/site-packages/redis/client.py", line 3576, in _execute_transaction
    self.parse_response(connection, '_')
  File "/home/zheng/anaconda2/envs/tf/lib/python3.6/site-packages/redis/client.py", line 3650, in parse_response
    self, connection, command_name, **options)
  File "/home/zheng/anaconda2/envs/tf/lib/python3.6/site-packages/redis/client.py", line 853, in parse_response
    response = connection.read_response()
  File "/home/zheng/anaconda2/envs/tf/lib/python3.6/site-packages/redis/connection.py", line 718, in read_response
    raise response
redis.exceptions.ResponseError: Command # 1 (SETEX b'celery-task-meta-0e824adc-2253-4ddb-8b5b-91cf57c908e9' 86400 b'\x80\x02}q\x00(X\x06\x00\x00\x00statusq\x01X\x07\x00\x00\x00FAILUREq\x02X\x06\x00\x00\x00resultq\x03credis.exceptions\nResponseError\nq\x04X\xbd\x17\x00\x00Command # 1 (SETEX b\'celery-task-meta-0e824adc-2253-4ddb-8b5b-91cf57c908e9\' 86400 b\'\\x80\\x02}q\\x00(X\\x06\\x00\\x00\\x00statusq\\x01X\\x07\\x00\\x00\\x00FAILUREq\\x02X\\x06\\x00\\x00\\x00resultq\\x03credis.exceptions\\nResponseError\\nq\\x04X\\x92\\x03\\x00\\x00Command # 1 (SETEX b\\\'celery-task-meta-0e824adc-2253-4ddb-8b5b-91cf57c908e9\\\' 86400 b\\\'\\\\x80\\\\x02}q\\\\x00(X\\\\x06\\\\x00\\\\x00\\\\x00statusq\\\\x01X\\\\x07\\\\x00\\\\x00\\\\x00SUCCESSq\\\\x02X\\\\x06\\\\x00\\\\x00\\\\x00resultq\\\\x03X\\\\x00\\\\x00\\\\x00\\\\x00q\\\\x04X\\\\t\\\\x00\\\\x00\\\\x00tracebackq\\\\x05NX\\\\x08\\\\x00\\\\x00\\\\x00childrenq\\\\x06]q\\\\x07X\\\\x07\\\\x00\\\\x00\\\\x00task_idq\\\\x08X$\\\\x00\\\\x00\\\\x000e824adc-2253-4ddb-8b5b-91cf57c908e9q\\\\tX\\\\t\\\\x00\\\\x00\\\\x00date_doneq\\\\ncdatetime\\\\ndatetime\\\\nq\\\\x0bc_codecs\\\\nencode\\\\nq\\\\x0cX\\\\x0b\\\\x00\\\\x00\\\\x00\\\\x07\\\\xc3\\\\xa3\\\\x0b\\\\x1b\\\\x11))\\\\x08z|q\\\\rX\\\\x06\\\\x00\\\\x00\\\\x00latin1q\\\\x0e\\\\x86q\\\\x0fRq\\\\x10\\\\x85q\\\\x11Rq\\\\x12u.\\\') of pipeline caused error: MISCONF Redis is configured to save RDB snapshots, but it is currently not able to persist on disk. Commands that may modify the data set are disabled, because this instance is configured to report errors during writes if RDB snapshotting fails (stop-writes-on-bgsave-error option). Please check the Redis logs for details about the RDB error.q\\x05\\x85q\\x06Rq\\x07X\\t\\x00\\x00\\x00tracebackq\\x08Xv\\x0f\\x00\\x00Traceback (most recent call last):\\n  File "/home/zheng/anaconda2/envs/tf/lib/python3.6/site-packages/redis/client.py", line 3584, in _execute_transaction\\n    response = self.parse_response(connection, \\\'_\\\')\\n  File "/home/zheng/anaconda2/envs/tf/lib/python3.6/site-packages/redis/client.py", line 3650, in parse_response\\n    self, connection, command_name, **options)\\n  File "/home/zheng/anaconda2/envs/tf/lib/python3.6/site-packages/redis/client.py", line 853, in parse_response\\n    response = connection.read_response()\\n  File "/home/zheng/anaconda2/envs/tf/lib/python3.6/site-packages/redis/connection.py", line 718, in read_response\\n    raise response\\nredis.exceptions.ExecAbortError: Transaction discarded because of previous errors.\\n\\nDuring handling of the above exception, another exception occurred:\\n\\nTraceback (most recent call last):\\n  File "/home/zheng/anaconda2/envs/tf/lib/python3.6/site-packages/celery/app/trace.py", line 449, in trace_task\\n    uuid, retval, task_request, publish_result,\\n  File "/home/zheng/anaconda2/envs/tf/lib/python3.6/site-packages/celery/backends/base.py", line 149, in mark_as_done\\n    self.store_result(task_id, result, state, request=request)\\n  File "/home/zheng/anaconda2/envs/tf/lib/python3.6/site-packages/celery/backends/base.py", line 342, in store_result\\n    request=request, **kwargs)\\n  File "/home/zheng/anaconda2/envs/tf/lib/python3.6/site-packages/celery/backends/base.py", line 714, in _store_result\\n    self.set(self.get_key_for_task(task_id), self.encode(meta))\\n  File "/home/zheng/anaconda2/envs/tf/lib/python3.6/site-packages/celery/backends/redis.py", line 318, in set\\n    return self.ensure(self._set, (key, value), **retry_policy)\\n  File "/home/zheng/anaconda2/envs/tf/lib/python3.6/site-packages/celery/backends/redis.py", line 308, in ensure\\n    **retry_policy)\\n  File "/home/zheng/anaconda2/envs/tf/lib/python3.6/site-packages/kombu/utils/functional.py", line 343, in retry_over_time\\n    return fun(*args, **kwargs)\\n  File "/home/zheng/anaconda2/envs/tf/lib/python3.6/site-packages/celery/backends/redis.py", line 327, in _set\\n    pipe.execute()\\n  File "/home/zheng/anaconda2/envs/tf/lib/python3.6/site-packages/redis/client.py", line 3691, in execute\\n    return execute(conn, stack, raise_on_error)\\n  File "/home/zheng/anaconda2/envs/tf/lib/python3.6/site-packages/redis/client.py", line 3589, in _execute_transaction\\n    raise errors[0][1]\\n  File "/home/zheng/anaconda2/envs/tf/lib/python3.6/site-packages/redis/client.py", line 3576, in _execute_transaction\\n    self.parse_response(connection, \\\'_\\\')\\n  File "/home/zheng/anaconda2/envs/tf/lib/python3.6/site-packages/redis/client.py", line 3650, in parse_response\\n    self, connection, command_name, **options)\\n  File "/home/zheng/anaconda2/envs/tf/lib/python3.6/site-packages/redis/client.py", line 853, in parse_response\\n    response = connection.read_response()\\n  File "/home/zheng/anaconda2/envs/tf/lib/python3.6/site-packages/redis/connection.py", line 718, in read_response\\n    raise response\\nredis.exceptions.ResponseError: Command # 1 (SETEX b\\\'celery-task-meta-0e824adc-2253-4ddb-8b5b-91cf57c908e9\\\' 86400 b\\\'\\\\x80\\\\x02}q\\\\x00(X\\\\x06\\\\x00\\\\x00\\\\x00statusq\\\\x01X\\\\x07\\\\x00\\\\x00\\\\x00SUCCESSq\\\\x02X\\\\x06\\\\x00\\\\x00\\\\x00resultq\\\\x03X\\\\x00\\\\x00\\\\x00\\\\x00q\\\\x04X\\\\t\\\\x00\\\\x00\\\\x00tracebackq\\\\x05NX\\\\x08\\\\x00\\\\x00\\\\x00childrenq\\\\x06]q\\\\x07X\\\\x07\\\\x00\\\\x00\\\\x00task_idq\\\\x08X$\\\\x00\\\\x00\\\\x000e824adc-2253-4ddb-8b5b-91cf57c908e9q\\\\tX\\\\t\\\\x00\\\\x00\\\\x00date_doneq\\\\ncdatetime\\\\ndatetime\\\\nq\\\\x0bc_codecs\\\\nencode\\\\nq\\\\x0cX\\\\x0b\\\\x00\\\\x00\\\\x00\\\\x07\\\\xc3\\\\xa3\\\\x0b\\\\x1b\\\\x11))\\\\x08z|q\\\\rX\\\\x06\\\\x00\\\\x00\\\\x00latin1q\\\\x0e\\\\x86q\\\\x0fRq\\\\x10\\\\x85q\\\\x11Rq\\\\x12u.\\\') of pipeline caused error: MISCONF Redis is configured to save RDB snapshots, but it is currently not able to persist on disk. Commands that may modify the data set are disabled, because this instance is configured to report errors during writes if RDB snapshotting fails (stop-writes-on-bgsave-error option). Please check the Redis logs for details about the RDB error.\\nq\\tX\\x08\\x00\\x00\\x00childrenq\\n]q\\x0bX\\x07\\x00\\x00\\x00task_idq\\x0cX$\\x00\\x00\\x000e824adc-2253-4ddb-8b5b-91cf57c908e9q\\rX\\t\\x00\\x00\\x00date_doneq\\x0ecdatetime\\ndatetime\\nq\\x0fc_codecs\\nencode\\nq\\x10X\\x0c\\x00\\x00\\x00\\x07\\xc3\\xa3\\x0b\\x1b\\x11))\\x08\\xc3\\x97\\x07q\\x11X\\x06\\x00\\x00\\x00latin1q\\x12\\x86q\\x13Rq\\x14\\x85q\\x15Rq\\x16u.\') of pipeline caused error: MISCONF Redis is configured to save RDB snapshots, but it is currently not able to persist on disk. Commands that may modify the data set are disabled, because this instance is configured to report errors during writes if RDB snapshotting fails (stop-writes-on-bgsave-error option). Please check the Redis logs for details about the RDB error.q\x05\x85q\x06Rq\x07X\t\x00\x00\x00tracebackq\x08NX\x08\x00\x00\x00childrenq\t]q\nX\x07\x00\x00\x00task_idq\x0bX$\x00\x00\x000e824adc-2253-4ddb-8b5b-91cf57c908e9q\x0cX\t\x00\x00\x00date_doneq\rcdatetime\ndatetime\nq\x0ec_codecs\nencode\nq\x0fX\r\x00\x00\x00\x07\xc3\xa3\x0b\x1b\x11))\x08\xc3\xbc\xc3\x86q\x10X\x06\x00\x00\x00latin1q\x11\x86q\x12Rq\x13\x85q\x14Rq\x15u.') of pipeline caused error: MISCONF Redis is configured to save RDB snapshots, but it is currently not able to persist on disk. Commands that may modify the data set are disabled, because this instance is configured to report errors during writes if RDB snapshotting fails (stop-writes-on-bgsave-error option). Please check the Redis logs for details about the RDB error.
[2019-11-27 17:41:42,115: CRITICAL/MainProcess] Unrecoverable error: ResponseError('MISCONF Redis is configured to save RDB snapshots, but it is currently not able to persist on disk. Commands that may modify the data set are disabled, because this instance is configured to report errors during writes if RDB snapshotting fails (stop-writes-on-bgsave-error option). Please check the Redis logs for details about the RDB error.',)
Traceback (most recent call last):
  File "/home/zheng/anaconda2/envs/tf/lib/python3.6/site-packages/celery/worker/worker.py", line 205, in start
    self.blueprint.start(self)
  File "/home/zheng/anaconda2/envs/tf/lib/python3.6/site-packages/celery/bootsteps.py", line 119, in start
    step.start(parent)
  File "/home/zheng/anaconda2/envs/tf/lib/python3.6/site-packages/celery/bootsteps.py", line 369, in start
    return self.obj.start()
  File "/home/zheng/anaconda2/envs/tf/lib/python3.6/site-packages/celery/worker/consumer/consumer.py", line 318, in start
    blueprint.start(self)
  File "/home/zheng/anaconda2/envs/tf/lib/python3.6/site-packages/celery/bootsteps.py", line 119, in start
    step.start(parent)
  File "/home/zheng/anaconda2/envs/tf/lib/python3.6/site-packages/celery/worker/consumer/consumer.py", line 596, in start
    c.loop(*c.loop_args())
  File "/home/zheng/anaconda2/envs/tf/lib/python3.6/site-packages/celery/worker/loops.py", line 91, in asynloop
    next(loop)
  File "/home/zheng/anaconda2/envs/tf/lib/python3.6/site-packages/kombu/asynchronous/hub.py", line 362, in create_loop
    cb(*cbargs)
  File "/home/zheng/anaconda2/envs/tf/lib/python3.6/site-packages/kombu/transport/redis.py", line 1060, in on_readable
    self.cycle.on_readable(fileno)
  File "/home/zheng/anaconda2/envs/tf/lib/python3.6/site-packages/kombu/transport/redis.py", line 356, in on_readable
    chan.handlers[type]()
  File "/home/zheng/anaconda2/envs/tf/lib/python3.6/site-packages/kombu/transport/redis.py", line 733, in _brpop_read
    **options)
  File "/home/zheng/anaconda2/envs/tf/lib/python3.6/site-packages/redis/client.py", line 853, in parse_response
    response = connection.read_response()
  File "/home/zheng/anaconda2/envs/tf/lib/python3.6/site-packages/redis/connection.py", line 718, in read_response
    raise response
redis.exceptions.ResponseError: MISCONF Redis is configured to save RDB snapshots, but it is currently not able to persist on disk. Commands that may modify the data set are disabled, because this instance is configured to report errors during writes if RDB snapshotting fails (stop-writes-on-bgsave-error option). Please check the Redis logs for details about the RDB error.
